Workbook
Name IQ_CH: 110000
Name IQ_CQ: 5000
Name IQ_CY: 10000
Name IQ_DAILY: 500000
Name IQ_FH: 100000
Name IQ_FQ: 500
Name IQ_FY: 1000
Name IQ_LTM: 2000
Name IQ_MONTH: 15000
Name IQ_NTM: 6000
Name IQ_WEEK: 50000
Name IQ_YTD: 3000
Name UPDATE: 'Data Sheet'!$E$1

Sheet Financials>

Sheet HistoricalFS
B2: ="Historical Financial Statement - "&'Data Sheet'!B1 -> Historical Financial Statement - ITC LTD
B3: Years | C3: ='Data Sheet'!B16 -> 42825 | D3: ='Data Sheet'!C16 -> 43190 | E3: ='Data Sheet'!D16 -> 43555 | F3: ='Data Sheet'!E16 -> 43921 | G3: ='Data Sheet'!F16 -> 44286 | H3: ='Data Sheet'!G16 -> 44651 | I3: ='Data Sheet'!H16 -> 45016 | J3: ='Data Sheet'!I16 -> 45382 | ... L3: ='Data Sheet'!K16 -> 46112 | M3: LTM
A5: # | B5: Income Statement
B6: Sales | C6: =IFERROR('Data Sheet'!B17,0) -> 42767.6 | D6: =IFERROR('Data Sheet'!C17,0) -> 43448.94 | E6: =IFERROR('Data Sheet'!D17,0) -> 48339.58 | F6: =IFERROR('Data Sheet'!E17,0) -> 49387.7 | G6: =IFERROR('Data Sheet'!F17,0) -> 49257.45 | H6: =IFERROR('Data Sheet'!G17,0) -> 60644.54 | I6: =IFERROR('Data Sheet'!H17,0) -> 70919.03 | J6: =IFERROR('Data Sheet'!I17,0) -> 67931.94 | ... L6: =IFERROR('Data Sheet'!K17,0) -> 78868.4 | M6: =IFERROR(SUM('Data Sheet'!H42:K42),0) -> 78868.4
B7: Sales Growth | C7: - | D7: =D6/C6-1 -> 0.015931219 | E7: =E6/D6-1 -> 0.11256063 | F7: =F6/E6-1 -> 0.021682439 | G7: =G6/F6-1 -> -0.0026372963 | H7: =H6/G6-1 -> 0.23117498 | I7: =I6/H6-1 -> 0.16942152 | J7: =J6/I6-1 -> -0.042119724 | K7: =K6/J6-1 -> 0.10880596 | ... M7: =M6/L6-1 -> 0
B9: COGS | C9: =IFERROR(SUM('Data Sheet'!B18,'Data Sheet'!B20:B22)-1*'Data Sheet'!B19,0) -> 21949.12 | D9: =IFERROR(SUM('Data Sheet'!C18,'Data Sheet'!C20:C22)-1*'Data Sheet'!C19,0) -> 21967.5 | E9: =IFERROR(SUM('Data Sheet'!D18,'Data Sheet'!D20:D22)-1*'Data Sheet'!D19,0) -> 24215.95 | F9: =IFERROR(SUM('Data Sheet'!E18,'Data Sheet'!E20:E22)-1*'Data Sheet'!E19,0) -> 24330.4 | G9: =IFERROR(SUM('Data Sheet'!F18,'Data Sheet'!F20:F22)-1*'Data Sheet'!F19,0) -> 26881.51 | H9: =IFERROR(SUM('Data Sheet'!G18,'Data Sheet'!G20:G22)-1*'Data Sheet'!G19,0) -> 34053.06 | I9: =IFERROR(SUM('Data Sheet'!H18,'Data Sheet'!H20:H22)-1*'Data Sheet'!H19,0) -> 38302.13 | J9: =IFERROR(SUM('Data Sheet'!I18,'Data Sheet'!I20:I22)-1*'Data Sheet'!I19,0) -> 35665.99 | ... L9: =IFERROR(SUM('Data Sheet'!K18,'Data Sheet'!K20:K22)-1*'Data Sheet'!K19,0) -> 39329.38 | M9: =IFERROR(SUM('Data Sheet'!H43:K43),0) -> 51550.49
B10: COGS % Sales | C10: =C9/C6 -> 0.51321842 | D10: =D9/D6 -> 0.50559346 | E10: =E9/E6 -> 0.50095491 | F10: =F9/F6 -> 0.49264088 | G10: =G9/G6 -> 0.54573491 | H10: =H9/H6 -> 0.56151898 | I10: =I9/I6 -> 0.54008254 | J10: =J9/J6 -> 0.52502534 | ... M10: =M9/M6 -> 0.65362667
B12: Gross Profit | C12: =C6-C9 -> 20818.48 | D12: =D6-D9 -> 21481.44 | E12: =E6-E9 -> 24123.63 | F12: =F6-F9 -> 25057.3 | G12: =G6-G9 -> 22375.94 | H12: =H6-H9 -> 26591.48 | I12: =I6-I9 -> 32616.9 | J12: =J6-J9 -> 32265.95 | ... M12: =M6-M9 -> 27317.91
B13: Gross Margins | C13: =C12/C6 -> 0.48678158 | D13: =D12/D6 -> 0.49440654 | E13: =E12/E6 -> 0.49904509 | F13: =F12/F6 -> 0.50735912 | G13: =G12/G6 -> 0.45426509 | H13: =H12/H6 -> 0.43848102 | I13: =I12/I6 -> 0.45991746 | J13: =J12/J6 -> 0.47497466 | ... M13: =M12/M6 -> 0.34637333
B15: Selling & General Expenses | C15: =IFERROR(SUM('Data Sheet'!B23:B24),0) -> 5348.97 | D15: =IFERROR(SUM('Data Sheet'!C23:C24),0) -> 4960.85 | E15: =IFERROR(SUM('Data Sheet'!D23:D24),0) -> 5586.24 | F15: =IFERROR(SUM('Data Sheet'!E23:E24),0) -> 5713.76 | G15: =IFERROR(SUM('Data Sheet'!F23:F24),0) -> 5311.16 | H15: =IFERROR(SUM('Data Sheet'!G23:G24),0) -> 5968.33 | I15: =IFERROR(SUM('Data Sheet'!H23:H24),0) -> 6912.64 | J15: =IFERROR(SUM('Data Sheet'!I23:I24),0) -> 7078.42 | ... L15: =IFERROR(SUM('Data Sheet'!K23:K24),0) -> 12221.11
B16: S&G Exp % Sales | C16: =C15/C6 -> 0.12507061 | D16: =D15/D6 -> 0.11417655 | E16: =E15/E6 -> 0.11556244 | F16: =F15/F6 -> 0.11569196 | G16: =G15/G6 -> 0.1078245 | H16: =H15/H6 -> 0.09841496 | I16: =I15/I6 -> 0.097472286 | J16: =J15/J6 -> 0.1041987 | ... M16: =M15/M6 -> 0
B18: EBITDA | C18: =C12-C15 -> 15469.51 | D18: =D12-D15 -> 16520.59 | E18: =E12-E15 -> 18537.39 | F18: =F12-F15 -> 19343.54 | G18: =G12-G15 -> 17064.78 | H18: =H12-H15 -> 20623.15 | I18: =I12-I15 -> 25704.26 | J18: =J12-J15 -> 25187.53 | ... L18: =L12-L15 -> 27317.91 | M18: =IFERROR(SUM('Data Sheet'!H51:K51),0) -> 29500.41
B19: EBITDA Margins | C19: =C18/C6 -> 0.36171097 | D19: =D18/D6 -> 0.38022999 | E19: =E18/E6 -> 0.38348265 | F19: =F18/F6 -> 0.39166716 | G19: =G18/G6 -> 0.34644059 | H19: =H18/H6 -> 0.34006606 | I19: =I18/I6 -> 0.36244517 | J19: =J18/J6 -> 0.37077596 | ... M19: =M18/M6 -> 0.37404601
B21: Interest | C21: =IFERROR('Data Sheet'!B27,0) -> 49.03 | D21: =IFERROR('Data Sheet'!C27,0) -> 115.01 | E21: =IFERROR('Data Sheet'!D27,0) -> 71.4 | F21: =IFERROR('Data Sheet'!E27,0) -> 81.38 | G21: =IFERROR('Data Sheet'!F27,0) -> 57.97 | H21: =IFERROR('Data Sheet'!G27,0) -> 59.99 | I21: =IFERROR('Data Sheet'!H27,0) -> 77.77 | J21: =IFERROR('Data Sheet'!I27,0) -> 39.11 | ... L21: =IFERROR('Data Sheet'!K27,0) -> 85.17 | M21: =IFERROR(SUM('Data Sheet'!H46:K46),0) -> 85.17
B22: Interest % Sales | C22: =C21/C6 -> 0.0011464286 | D22: =D21/D6 -> 0.0026470151 | E22: =E21/E6 -> 0.0014770505 | F22: =F21/F6 -> 0.0016477787 | G22: =G21/G6 -> 0.0011768778 | H22: =H21/H6 -> 0.00098920694 | I22: =I21/I6 -> 0.0010966027 | J22: =J21/J6 -> 0.00057572329 | ... M22: =M21/M6 -> 0.0010799002
B24: Depreciation | C24: =IFERROR('Data Sheet'!B26,0) -> 1152.79 | D24: =IFERROR('Data Sheet'!C26,0) -> 1236.28 | E24: =IFERROR('Data Sheet'!D26,0) -> 1396.61 | F24: =IFERROR('Data Sheet'!E26,0) -> 1644.91 | G24: =IFERROR('Data Sheet'!F26,0) -> 1645.59 | H24: =IFERROR('Data Sheet'!G26,0) -> 1732.41 | I24: =IFERROR('Data Sheet'!H26,0) -> 1809.01 | J24: =IFERROR('Data Sheet'!I26,0) -> 1518.05 | ... L24: =IFERROR('Data Sheet'!K26,0) -> 1710.53 | M24: =IFERROR(SUM('Data Sheet'!H45:K45),0) -> 1710.53
B25: Depreciation%Sales | C25: =C24/C6 -> 0.026954751 | D25: =D24/D6 -> 0.028453629 | E25: =E24/E6 -> 0.028891645 | F25: =F24/F6 -> 0.033306066 | G25: =G24/G6 -> 0.033407941 | H25: =H24/H6 -> 0.028566628 | I25: =I24/I6 -> 0.025508104 | J25: =J24/J6 -> 0.022346631 | ... M25: =M24/M6 -> 0.021688408
B27: Earnings Before Tax | C27: =IFERROR(C18-SUM(C24,C21),0) -> 14267.69 | D27: =IFERROR(D18-SUM(D24,D21),0) -> 15169.3 | E27: =IFERROR(E18-SUM(E24,E21),0) -> 17069.38 | F27: =IFERROR(F18-SUM(F24,F21),0) -> 17617.25 | G27: =IFERROR(G18-SUM(G24,G21),0) -> 15361.22 | H27: =IFERROR(H18-SUM(H24,H21),0) -> 18830.75 | I27: =IFERROR(I18-SUM(I24,I21),0) -> 23817.48 | J27: =IFERROR(J18-SUM(J24,J21),0) -> 23630.37 | ... M27: =IFERROR(M18-SUM(M24,M21),0) -> 27704.71
B28: EBT % Sales | C28: =C27/C6 -> 0.33360979 | D28: =D27/D6 -> 0.34912935 | E28: =E27/E6 -> 0.35311395 | F28: =F27/F6 -> 0.35671331 | G28: =G27/G6 -> 0.31185577 | H28: =H27/H6 -> 0.31051023 | I28: =I27/I6 -> 0.33584046 | J28: =J27/J6 -> 0.3478536 | ... M28: =M27/M6 -> 0.3512777
B30: Tax | C30: =IFERROR('Data Sheet'!B29,0) -> 5549.09 | D30: =IFERROR('Data Sheet'!C29,0) -> 5916.43 | E30: =IFERROR('Data Sheet'!D29,0) -> 6313.92 | F30: =IFERROR('Data Sheet'!E29,0) -> 4441.79 | G30: =IFERROR('Data Sheet'!F29,0) -> 4555.29 | H30: =IFERROR('Data Sheet'!G29,0) -> 5237.34 | I30: =IFERROR('Data Sheet'!H29,0) -> 6438.4 | J30: =IFERROR('Data Sheet'!I29,0) -> 6209.46 | ... L30: =IFERROR('Data Sheet'!K29,0) -> 7015.24 | M30: =IFERROR(SUM('Data Sheet'!H48:K48),0) -> 7015.24
B31: Effective Tax Rate | C31: =C30/C27 -> 0.38892701 | D31: =D30/D27 -> 0.39002657 | E31: =E30/E27 -> 0.36989744 | F31: =F30/F27 -> 0.25212732 | G31: =G30/G27 -> 0.29654481 | H31: =H30/H27 -> 0.278127 | I31: =I30/I27 -> 0.27032247 | J31: =J30/J27 -> 0.26277456 | ... M31: =M30/M27 -> 0.25321471
B33: Net Profit | C33: =IFERROR(C27-C30,0) -> 8718.6 | D33: =IFERROR(D27-D30,0) -> 9252.87 | E33: =IFERROR(E27-E30,0) -> 10755.46 | F33: =IFERROR(F27-F30,0) -> 13175.46 | G33: =IFERROR(G27-G30,0) -> 10805.93 | H33: =IFERROR(H27-H30,0) -> 13593.41 | I33: =IFERROR(I27-I30,0) -> 17379.08 | J33: =IFERROR(J27-J30,0) -> 17420.91 | ... M33: =IFERROR(M27-M30,0) -> 20689.47
B34: Net Margins | C34: =C33/C6 -> 0.20385993 | D34: =D33/D6 -> 0.21295963 | E34: =E33/E6 -> 0.222498 | F34: =F33/F6 -> 0.26677614 | G34: =G33/G6 -> 0.21937656 | H34: =H33/H6 -> 0.22414895 | I34: =I33/I6 -> 0.24505524 | J34: =J33/J6 -> 0.25644653 | ... M34: =M33/M6 -> 0.26232902
B36: No of Equity Shares | C36: =IFERROR('Data Sheet'!B93,0) -> 1214.74 | D36: =IFERROR('Data Sheet'!C93,0) -> 1220.43 | E36: =IFERROR('Data Sheet'!D93,0) -> 1225.86 | F36: =IFERROR('Data Sheet'!E93,0) -> 1229.22 | G36: =IFERROR('Data Sheet'!F93,0) -> 1230.88 | H36: =IFERROR('Data Sheet'!G93,0) -> 1232.33 | I36: =IFERROR('Data Sheet'!H93,0) -> 1242.8 | J36: =IFERROR('Data Sheet'!I93,0) -> 1248.47 | ... L36: =IFERROR('Data Sheet'!K93,0) -> 1252.95 | M36: =L36 -> 1252.95
B38: Earnings per Share | C38: =IFERROR(C33/C36,0) -> 7.1773384 | D38: =IFERROR(D33/D36,0) -> 7.5816475 | E38: =IFERROR(E33/E36,0) -> 8.7738078 | F38: =IFERROR(F33/F36,0) -> 10.718553 | G38: =IFERROR(G33/G36,0) -> 8.779028 | H38: =IFERROR(H33/H36,0) -> 11.030657 | I38: =IFERROR(I33/I36,0) -> 13.983811 | J38: =IFERROR(J33/J36,0) -> 13.953807 | ... M38: =IFERROR(M33/M36,0) -> 16.512606
B39: EPS Growth % | D39: =IFERROR(D38/C38-1,0) -> 0.056331341 | E39: =IFERROR(E38/D38-1,0) -> 0.15724291 | F39: =IFERROR(F38/E38-1,0) -> 0.22165353 | G39: =IFERROR(G38/F38-1,0) -> -0.18095028 | H39: =IFERROR(H38/G38-1,0) -> 0.25647821 | I39: =IFERROR(I38/H38-1,0) -> 0.26772234 | J39: =IFERROR(J38/I38-1,0) -> -0.0021455732 | K39: =IFERROR(K38/J38-1,0) -> -0.011701693 | ... M39: =IFERROR(M38/L38-1,0) -> 0.11792854
B41: Dividend per Share | C41: =IFERROR('Data Sheet'!B31/HistoricalFS!C36,0) -> 4.7500041 | D41: =IFERROR('Data Sheet'!C31/HistoricalFS!D36,0) -> 5.1499963 | E41: =IFERROR('Data Sheet'!D31/HistoricalFS!E36,0) -> 5.7500041 | F41: =IFERROR('Data Sheet'!E31/HistoricalFS!F36,0) -> 10.149998 | G41: =IFERROR('Data Sheet'!F31/HistoricalFS!G36,0) -> 10.75 | H41: =IFERROR('Data Sheet'!G31/HistoricalFS!H36,0) -> 11.500004 | I41: =IFERROR('Data Sheet'!H31/HistoricalFS!I36,0) -> 15.5 | J41: =IFERROR('Data Sheet'!I31/HistoricalFS!J36,0) -> 13.749998 | ... M41: =IFERROR('Data Sheet'!L31/HistoricalFS!M36,0) -> 0
B42: Dividend payout ratio | C42: =IFERROR(C41/C38,0) -> 0.66180579 | D42: =IFERROR(D41/D38,0) -> 0.6792714 | E42: =IFERROR(E41/E38,0) -> 0.65536016 | F42: =IFERROR(F41/F38,0) -> 0.94695593 | G42: =IFERROR(G41/G38,0) -> 1.2245091 | H42: =IFERROR(H41/H38,0) -> 1.0425493 | I42: =IFERROR(I41/I38,0) -> 1.1084246 | J42: =IFERROR(J41/J38,0) -> 0.98539399 | ... M42: =IFERROR(M41/M38,0) -> 0
B44: Retained Earnings | C44: =IFERROR(IF(C38>C41,1-C42,0),0) -> 0.33819421 | D44: =IFERROR(IF(D38>D41,1-D42,0),0) -> 0.3207286 | E44: =IFERROR(IF(E38>E41,1-E42,0),0) -> 0.34463984 | F44: =IFERROR(IF(F38>F41,1-F42,0),0) -> 0.053044068 | G44: =IFERROR(IF(G38>G41,1-G42,0),0) -> 0 | H44: =IFERROR(IF(H38>H41,1-H42,0),0) -> 0 | I44: =IFERROR(IF(I38>I41,1-I42,0),0) -> 0 | J44: =IFERROR(IF(J38>J41,1-J42,0),0) -> 0.014606011 | ... M44: =IFERROR(IF(M38>M41,1-M42,0),0) -> 1
A46: # | B46: Balance Sheet
B47: Equity Share Capital | C47: =IFERROR('Data Sheet'!B57,0) -> 1214.74 | D47: =IFERROR('Data Sheet'!C57,0) -> 1220.43 | E47: =IFERROR('Data Sheet'!D57,0) -> 1225.86 | F47: =IFERROR('Data Sheet'!E57,0) -> 1229.22 | G47: =IFERROR('Data Sheet'!F57,0) -> 1230.88 | H47: =IFERROR('Data Sheet'!G57,0) -> 1232.33 | I47: =IFERROR('Data Sheet'!H57,0) -> 1242.8 | J47: =IFERROR('Data Sheet'!I57,0) -> 1248.47 | ... L47: =IFERROR('Data Sheet'!K57,0) -> 1252.95
B48: Reserves | C48: =IFERROR('Data Sheet'!B58,0) -> 45198.19 | D48: =IFERROR('Data Sheet'!C58,0) -> 51289.68 | E48: =IFERROR('Data Sheet'!D58,0) -> 57915.01 | F48: =IFERROR('Data Sheet'!E58,0) -> 64044.04 | G48: =IFERROR('Data Sheet'!F58,0) -> 59116.46 | H48: =IFERROR('Data Sheet'!G58,0) -> 61223.24 | I48: =IFERROR('Data Sheet'!H58,0) -> 67912.46 | J48: =IFERROR('Data Sheet'!I58,0) -> 73258.53 | ... L48: =IFERROR('Data Sheet'!K58,0) -> 71254.35
B49: Borrowings | C49: =IFERROR('Data Sheet'!B59,0) -> 45.72 | D49: =IFERROR('Data Sheet'!C59,0) -> 35.92 | E49: =IFERROR('Data Sheet'!D59,0) -> 13.44 | F49: =IFERROR('Data Sheet'!E59,0) -> 277.45 | G49: =IFERROR('Data Sheet'!F59,0) -> 270.83 | H49: =IFERROR('Data Sheet'!G59,0) -> 249.44 | I49: =IFERROR('Data Sheet'!H59,0) -> 306.04 | J49: =IFERROR('Data Sheet'!I59,0) -> 303.43 | ... L49: =IFERROR('Data Sheet'!K59,0) -> 2399.06
B50: Other Liabilities | C50: =IFERROR('Data Sheet'!B60,0) -> 9439.67 | D50: =IFERROR('Data Sheet'!C60,0) -> 11694.85 | E50: =IFERROR('Data Sheet'!D60,0) -> 12584.73 | F50: =IFERROR('Data Sheet'!E60,0) -> 11760.04 | G50: =IFERROR('Data Sheet'!F60,0) -> 13142.59 | H50: =IFERROR('Data Sheet'!G60,0) -> 14491.01 | I50: =IFERROR('Data Sheet'!H60,0) -> 16369.66 | J50: =IFERROR('Data Sheet'!I60,0) -> 16943.54 | ... L50: =IFERROR('Data Sheet'!K60,0) -> 18886.02
B51: Total Liabilities | C51: =IFERROR('Data Sheet'!B61,0) -> 55898.32 | D51: =IFERROR('Data Sheet'!C61,0) -> 64240.88 | E51: =IFERROR('Data Sheet'!D61,0) -> 71739.04 | F51: =IFERROR('Data Sheet'!E61,0) -> 77310.75 | G51: =IFERROR('Data Sheet'!F61,0) -> 73760.76 | H51: =IFERROR('Data Sheet'!G61,0) -> 77196.02 | I51: =IFERROR('Data Sheet'!H61,0) -> 85830.96 | J51: =IFERROR('Data Sheet'!I61,0) -> 91753.97 | ... L51: =IFERROR('Data Sheet'!K61,0) -> 93792.38
B53: Fixed Assets Net Block | C53: =IFERROR('Data Sheet'!B62,0) -> 15893.48 | D53: =IFERROR('Data Sheet'!C62,0) -> 16523.96 | E53: =IFERROR('Data Sheet'!D62,0) -> 19374.19 | F53: =IFERROR('Data Sheet'!E62,0) -> 21713.34 | G53: =IFERROR('Data Sheet'!F62,0) -> 23298.48 | H53: =IFERROR('Data Sheet'!G62,0) -> 24231.59 | I53: =IFERROR('Data Sheet'!H62,0) -> 25851.27 | J53: =IFERROR('Data Sheet'!I62,0) -> 27820.22 | ... L53: =IFERROR('Data Sheet'!K62,0) -> 22545
B54: Capital Work in Progress | C54: =IFERROR('Data Sheet'!B63,0) -> 3729.89 | D54: =IFERROR('Data Sheet'!C63,0) -> 5508.33 | E54: =IFERROR('Data Sheet'!D63,0) -> 4136.42 | F54: =IFERROR('Data Sheet'!E63,0) -> 3256.46 | G54: =IFERROR('Data Sheet'!F63,0) -> 4011.29 | H54: =IFERROR('Data Sheet'!G63,0) -> 3225.54 | I54: =IFERROR('Data Sheet'!H63,0) -> 3003.3 | J54: =IFERROR('Data Sheet'!I63,0) -> 2860.78 | ... L54: =IFERROR('Data Sheet'!K63,0) -> 1499.41
B55: Investments | C55: =IFERROR('Data Sheet'!B64,0) -> 17581.38 | D55: =IFERROR('Data Sheet'!C64,0) -> 22052.86 | E55: =IFERROR('Data Sheet'!D64,0) -> 25043.49 | F55: =IFERROR('Data Sheet'!E64,0) -> 28663.35 | G55: =IFERROR('Data Sheet'!F64,0) -> 24870.87 | H55: =IFERROR('Data Sheet'!G64,0) -> 24841.01 | I55: =IFERROR('Data Sheet'!H64,0) -> 29415.02 | J55: =IFERROR('Data Sheet'!I64,0) -> 31114.02 | ... L55: =IFERROR('Data Sheet'!K64,0) -> 38128.43
B56: Other Assets | C56: =IFERROR('Data Sheet'!B65-SUM('Data Sheet'!B67:B69),0) -> 5135.78 | D56: =IFERROR('Data Sheet'!C65-SUM('Data Sheet'!C67:C69),0) -> 7078.75 | E56: =IFERROR('Data Sheet'!D65-SUM('Data Sheet'!D67:D69),0) -> 7138.07 | F56: =IFERROR('Data Sheet'!E65-SUM('Data Sheet'!E67:E69),0) -> 4958.45 | G56: =IFERROR('Data Sheet'!F65-SUM('Data Sheet'!F67:F69),0) -> 4022.24 | H56: =IFERROR('Data Sheet'!G65-SUM('Data Sheet'!G67:G69),0) -> 6917.41 | I56: =IFERROR('Data Sheet'!H65-SUM('Data Sheet'!H67:H69),0) -> 7953.85 | J56: =IFERROR('Data Sheet'!I65-SUM('Data Sheet'!I67:I69),0) -> 4562.57 | ... L56: =IFERROR('Data Sheet'!K65-SUM('Data Sheet'!K67:K69),0) -> 6064.93
B57: Total Non Current Assets | C57: =SUM(C53:C56) -> 42340.53 | D57: =SUM(D53:D56) -> 51163.9 | E57: =SUM(E53:E56) -> 55692.17 | F57: =SUM(F53:F56) -> 58591.6 | G57: =SUM(G53:G56) -> 56202.88 | H57: =SUM(H53:H56) -> 59215.55 | I57: =SUM(I53:I56) -> 66223.44 | J57: =SUM(J53:J56) -> 66357.59 | ... L57: =SUM(L53:L56) -> 68237.77
...

Sheet Data>

Sheet Data Sheet
A1: COMPANY NAME | B1: ITC LTD | E1: =IF(B2<>B3, "A NEW VERSION OF THE WORKSHEET IS AVAILABLE", "")
A2: LATEST VERSION | B2: 2.1 | E2: PLEASE DO NOT MAKE ANY CHANGES TO THIS SHEET
A3: CURRENT VERSION | B3: 2.1
A5: META
A6: Number of shares | B6: =IF(B9>0, B9/B8, 0) -> 1252.9468
A7: Face Value | B7: 1
A8: Current Price | B8: 289.85
A9: Market Capitalization | B9: 363166.62
A15: PROFIT & LOSS | B15: =B26+B34 -> 18193.14 | K15: =K17-K18-K20-K21-K22-K23-K19 -> 34438.1
A16: Report Date | B16: 42825 | C16: 43190 | D16: 43555 | E16: 43921 | F16: 44286 | G16: 44651 | H16: 45016 | I16: 45382 | J16: 45747 | K16: 46112
A17: Sales | B17: 42767.6 | C17: 43448.94 | D17: 48339.58 | E17: 49387.7 | F17: 49257.45 | G17: 60644.54 | H17: 70919.03 | I17: 67931.94 | J17: 75323.34 | K17: 78868.4
A18: Raw Material Cost | B18: 15456.59 | C18: 14827.72 | D18: 17623.52 | E18: 18048.6 | F18: 20776.71 | G18: 27071.07 | H18: 29364.36 | I18: 27348.57 | J18: 32704.37 | K18: 35098.34
A19: Change in Inventory | B19: -592.57 | C19: -1027.76 | D19: 203.19 | E19: 703.13 | F19: 645.27 | G19: 686 | H19: 358.59 | I19: 367.77 | J19: 725.65 | K19: 2550.46
A20: Power and Fuel | B20: 584.33 | C20: 653.5 | D20: 746.73 | E20: 780.85 | F20: 699.56 | G20: 889.77 | H20: 1232.34 | I20: 952.9 | J20: 975.35
A21: Other Mfr. Exp | B21: 1683.9 | C21: 1697.62 | D21: 1871.01 | E21: 1908.29 | F21: 1587.18 | G21: 1887.67 | H21: 2327.8 | I21: 2183.76 | J21: 2345.36
A22: Employee Cost | B22: 3631.73 | C22: 3760.9 | D22: 4177.88 | E22: 4295.79 | F22: 4463.33 | G22: 4890.55 | H22: 5736.22 | I22: 5548.53 | J22: 6169.78 | K22: 6781.5
A23: Selling and admin | B23: 4179.74 | C23: 3954.87 | D23: 4546.39 | E23: 4488.63 | F23: 4236.77 | G23: 4858.38 | H23: 5604.08 | I23: 5312.45 | J23: 5793.29
A24: Other Expenses | B24: 1169.23 | C24: 1005.98 | D24: 1039.85 | E24: 1225.13 | F24: 1074.39 | G24: 1109.95 | H24: 1308.56 | I24: 1765.97 | J24: 2221.39 | K24: 12221.11
A25: Other Income | B25: 1758.63 | C25: 2239.81 | D25: 2080.44 | E25: 2417.32 | F25: 2576.95 | G25: 1909.72 | H25: 2097.64 | I25: 3330.45 | J25: 17794.88 | K25: 2511.18
A26: Depreciation | B26: 1152.79 | C26: 1236.28 | D26: 1396.61 | E26: 1644.91 | F26: 1645.59 | G26: 1732.41 | H26: 1809.01 | I26: 1518.05 | J26: 1646.32 | K26: 1710.53
A27: Interest | B27: 49.03 | C27: 115.01 | D27: 71.4 | E27: 81.38 | F27: 57.97 | G27: 59.99 | H27: 77.77 | I27: 39.11 | J27: 45.06 | K27: 85.17
A28: Profit before tax | B28: 16026.32 | C28: 17409.11 | D28: 19149.82 | E28: 20034.57 | F28: 17938.17 | G28: 20740.47 | H28: 25915.12 | I28: 26960.82 | J28: 41942.95 | K28: 28033.39
A29: Tax | B29: 5549.09 | C29: 5916.43 | D29: 6313.92 | E29: 4441.79 | F29: 4555.29 | G29: 5237.34 | H29: 6438.4 | I29: 6209.46 | J29: 6890.47 | K29: 7015.24
A30: Net profit | B30: 10289.44 | C30: 11271.2 | D30: 12592.33 | E30: 15306.23 | F30: 13161.19 | G30: 15242.66 | H30: 19191.66 | I30: 20458.78 | J30: 34746.63 | K30: 20689.47
A31: Dividend Amount | B31: 5770.02 | C31: 6285.21 | D31: 7048.7 | E31: 12476.58 | F31: 13231.96 | G31: 14171.8 | H31: 19263.4 | I31: 17166.46 | J31: 17957.73 | K31: 18167.78
A32: Effective Tax Rate | B32: =B29/B28 -> 0.34624855 | C32: =C29/C28 -> 0.33984678 | D32: =D29/D28 -> 0.32971172 | E32: =E29/E28 -> 0.22170628 | F32: =F29/F28 -> 0.25394396 | G32: =G29/G28 -> 0.2525179 | H32: =H29/H28 -> 0.24844184 | I32: =I29/I28 -> 0.23031421 | ... K32: =K29/K28 -> 0.25024587
A34: EBITDA | B34: =+B30+B29+B27+B26 -> 17040.35 | C34: =+C30+C29+C27+C26 -> 18538.92 | D34: =+D30+D29+D27+D26 -> 20374.26 | E34: =+E30+E29+E27+E26 -> 21474.31 | F34: =+F30+F29+F27+F26 -> 19420.04 | G34: =+G30+G29+G27+G26 -> 22272.4 | H34: =+H30+H29+H27+H26 -> 27516.84 | I34: =+I30+I29+I27+I26 -> 28225.4 | ... K34: =+K30+K29+K27+K26 -> 29500.41
A40: Quarters
A41: Report Date | B41: 45291 | C41: 45382 | D41: 45473 | E41: 45565 | F41: 45657 | G41: 45747 | H41: 45838 | I41: 45930 | J41: 46022 | K41: 46112
A42: Sales | B42: 17195.24 | C42: 17037.8 | D42: 17777.81 | E42: 19990.36 | F42: 18790.17 | G42: 18765 | H42: 21494.79 | I42: 19501.63 | J42: 20047.3 | K42: 17824.68
A43: Expenses | B43: 10985.01 | C43: 10735.73 | D43: 11232.97 | E43: 13438.28 | F43: 12428.27 | G43: 12245.61 | H43: 14678.32 | I43: 12806.94 | J43: 13164.78 | K43: 10900.45
A44: Other Income | B44: 820.26 | C44: 868 | D44: 771.13 | E44: 690.31 | F44: 803.4 | G44: 15391.28 | H44: 750.97 | I44: 738.84 | J44: 321.85 | K44: 699.52
A45: Depreciation | B45: 384.04 | C45: 385.09 | D45: 403.13 | E45: 416.18 | F45: 415.98 | G45: 411.03 | H45: 422.96 | I45: 434.8 | J45: 430.82 | K45: 421.95
A46: Interest | B46: 11.94 | C46: 10.72 | D46: 9.6 | E46: 14.73 | F46: 9.82 | G46: 10.91 | H46: 16.47 | I46: 20.05 | J46: 19.47 | K46: 29.18
A47: Profit before tax | B47: 6634.51 | C47: 6774.26 | D47: 6903.24 | E47: 6811.48 | F47: 6739.5 | G47: 21488.73 | H47: 7128.01 | I47: 6978.68 | J47: 6754.08 | K47: 7172.62
A48: Tax | B48: 1227.99 | C48: 1583.55 | D48: 1726.25 | E48: 1757.05 | F48: 1726.32 | G48: 1680.85 | H48: 1784.6 | I48: 1792.13 | J48: 1735.63 | K48: 1702.88
A49: Net profit | B49: 5335.23 | C49: 5120.55 | D49: 5091.59 | E49: 4992.87 | F49: 4934.8 | G49: 19727.37 | H49: 5244.2 | I49: 5126.11 | J49: 4931.19 | K49: 5387.97
A50: Operating Profit | B50: 6210.23 | C50: 6302.07 | D50: 6544.84 | E50: 6552.08 | F50: 6361.9 | G50: 6519.39 | H50: 6816.47 | I50: 6694.69 | J50: 6882.52 | K50: 6924.23
A51: EBITDA | B51: =B49+B48+B46+B45 -> 6959.2 | C51: =C49+C48+C46+C45 -> 7099.91 | D51: =D49+D48+D46+D45 -> 7230.57 | E51: =E49+E48+E46+E45 -> 7180.83 | F51: =F49+F48+F46+F45 -> 7086.92 | G51: =G49+G48+G46+G45 -> 21830.16 | H51: =H49+H48+H46+H45 -> 7468.23 | I51: =I49+I48+I46+I45 -> 7373.09 | ... K51: =K49+K48+K46+K45 -> 7541.98
A55: BALANCE SHEET
...

Sheet Cash Flow Data
C2: 40603 | D2: 40969 | E2: 41334 | F2: 41699 | G2: 42064 | H2: 42430 | I2: 42795 | J2: 43160 | K2: 43525 | L2: 43891 | M2: 44256 | N2: 44621
B3: Cash from Operating Activity - | C3: 11240 | D3: 18384 | E3: 22163 | F3: 36151 | G3: 35531 | H3: 37900 | I3: 30199 | J3: 23857 | K3: 18891 | L3: 26633 | M3: 29001 | N3: 14283
B4: Profit from operations | C4: 16680 | D4: 22432 | E4: 24406 | F4: 36303 | G4: 43397 | H4: 38626 | I4: 28840 | J4: 33312 | K4: 28771 | L4: 23352 | M4: 31198 | N4: 26666
B5: Receivables | C5: -1422 | D5: -6659 | E5: -5177 | F5: 445 | G5: -3179 | H5: -2223 | I5: -4152 | J5: -10688 | K5: -9109 | L5: 9950 | M5: -5505 | N5: 337
B6: Inventory | C6: -2411 | D6: -2719 | E6: -2656 | F6: -2853 | G6: -3692 | H6: -5743 | I6: -6621 | J6: -3560 | K6: 2069 | L6: 2326 | M6: 3814 | N6: 597
B7: Payables | C7: 344 | D7: 5867 | E7: 8132 | F7: 4694 | G7: 3598 | H7: 3947 | I7: 9301 | J7: 7320 | K7: -4692 | L7: -8085 | M7: 5748 | N7: -7012
B8: Loans Advances | C8: 0 | D8: 0 | E8: 0 | F8: 0 | G8: 0 | H8: -520 | I8: 0 | J8: 0 | K8: 0 | L8: 0 | M8: 0 | N8: 0
B9: Other WC items | C9: -559 | D9: 1231 | E9: -303 | F9: 1870 | G9: -398 | H9: 5852 | I9: 4727 | J9: 494 | K9: 4512 | L9: 875 | M9: -4150 | N9: -4396
B10: Working capital changes | C10: -4048 | D10: -2280 | E10: -3 | F10: 4157 | G10: -3672 | H10: 1313 | I10: 3254 | J10: -6434 | K10: -7221 | L10: 5065 | M10: -93 | N10: -10474
B11: Direct taxes | C11: -1391 | D11: -1768 | E11: -2240 | F11: -4308 | G11: -4194 | H11: -2040 | I11: -1895 | J11: -3021 | K11: -2659 | L11: -1785 | M11: -2105 | N11: -1910
B12: Cash from Investing Activity - | C12: -7023 | D12: -19464 | E12: -22969 | F12: -27991 | G12: -36232 | H12: -36694 | I12: -39571 | J12: -25139 | K12: -20878 | L12: -33115 | M12: -25672 | N12: -4444
B13: Fixed assets purchased | C13: -8124 | D13: -13876 | E13: -18863 | F13: -26975 | G13: -31962 | H13: -31503 | I13: -16072 | J13: -35079 | K13: -35304 | L13: -29702 | M13: -20205 | N13: -15168
B14: Fixed assets sold | C14: 11 | D14: 93 | E14: 37 | F14: 50 | G14: 74 | H14: 59 | I14: 53 | J14: 30 | K14: 67 | L14: 171 | M14: 351 | N14: 230
... B35: Net Cash Flow | C35: 2815 | D35: 5488 | E35: -2499 | F35: 4277 | G35: 4500 | H35: -2589 | I35: -3167 | J35: 730 | K35: 6843 | L35: -3092 | M35: 13232 | N35: 6459

Sheet DCF Model>

Sheet Raw FS 
B2: Particulars | C2: 42064 | D2: 42430 | E2: 42795 | F2: 43160 | G2: 43525 | H2: 43891 | I2: 44256 | J2: 44621 | K2: 44986 | L2: 45352 | M2: 45717
B4: Equity Capital | C4: 802 | D4: 805 | E4: 1215 | F4: 1220 | G4: 1226 | H4: 1229 | I4: 1231 | J4: 1232 | K4: 1243 | L4: 1248 | M4: 1251
B5: Reserves | C5: 30934 | D5: 41875 | E5: 45198 | F5: 51290 | G5: 57915 | H5: 64044 | I5: 59116 | J5: 61223 | K5: 67912 | L5: 73259 | M5: 68779
B7: Borrowings -
B8: Long term Borrowings | C8: 61 | D8: 27 | E8: 18 | F8: 12 | G8: 8 | H8: 6 | I8: 6 | J8: 5 | K8: 3 | L8: 2 | M8: 0
B9: Short term Borrowings | C9: 195 | D9: 44 | E9: 19 | F9: 17 | G9: 2 | H9: 1 | I9: 4 | J9: 1 | K9: 35 | L9: 10 | M9: 91
B10: Lease Liabilities | C10: 0 | D10: 0 | E10: 0 | F10: 0 | G10: 0 | H10: 268 | I10: 261 | J10: 244 | K10: 267 | L10: 292 | M10: 193
B11: Other Borrowings | C11: 13 | D11: 13 | E11: 8 | F11: 7 | G11: 3 | H11: 2 | I11: 0 | J11: 0 | K11: 0 | L11: 0 | M11: 0
B13: Other Liabilities -
B14: Non controlling int | C14: 225 | D14: 261 | E14: 295 | F14: 334 | G14: 343 | H14: 377 | I14: 347 | J14: 366 | K14: 384 | L14: 383 | M14: 368
B15: Trade Payables | C15: 2020 | D15: 2339 | E15: 2659 | F15: 3496 | G15: 3510 | H15: 3630 | I15: 4319 | J15: 4417 | K15: 4659 | L15: 4798 | M15: 4807
B16: Advance from Customers | C16: 0 | D16: 805 | E16: 495 | F16: 461 | G16: 430 | H16: 703 | I16: 811 | J16: 1278 | K16: 1295 | L16: 886 | M16: 1264
B17: Other liability items | C17: 11702 | D17: 5483 | E17: 5991 | F17: 7404 | G17: 8301 | H17: 7050 | I17: 7666 | J17: 8429 | K17: 10032 | L17: 10877 | M17: 11249
B18: Total Liabilities | C18: 45952 | D18: 51651 | E18: 55898 | F18: 64241 | G18: 71739 | H18: 77311 | I18: 73761 | J18: 77196 | K18: 85831 | L18: 91754 | M18: 88003
B20: Fixed Assets -
B21: Land | C21: 1717 | D21: 1615 | E21: 1673 | F21: 1685 | G21: 2021 | H21: 2797 | I21: 2889 | J21: 2829 | K21: 2830 | L21: 2865 | M21: 1588
B22: Building | C22: 4860 | D22: 4219 | E22: 4716 | F22: 5331 | G22: 6996 | H22: 8161 | I22: 8387 | J22: 9100 | K22: 9789 | L22: 10944 | M22: 7550
B23: Plant Machinery | C23: 14667 | D23: 9112 | E23: 10384 | F23: 11453 | G23: 13316 | H23: 14625 | I23: 15307 | J23: 16912 | K23: 18480 | L23: 20718 | M23: 19423
B24: Equipments | C24: 46 | D24: 27 | E24: 32 | F24: 32 | G24: 34 | H24: 40 | I24: 41 | J24: 44 | K24: 44 | L24: 53 | M24: 63
B25: Furniture n fittings | C25: 805 | D25: 413 | E25: 459 | F25: 497 | G25: 644 | H25: 810 | I25: 833 | J25: 907 | K25: 1000 | L25: 1068 | M25: 282
B26: Railway sidings | C26: 2 | D26: 2 | E26: 2 | F26: 2 | G26: 2 | H26: 2 | I26: 2 | J26: 2 | K26: 2 | L26: 2 | M26: 2
B27: Vehicles | C27: 128 | D27: 107 | E27: 128 | F27: 140 | G27: 161 | H27: 184 | I27: 180 | J27: 179 | K27: 189 | L27: 192 | M27: 141
B28: Intangible Assets | C28: 678 | D28: 563 | E28: 563 | F28: 570 | G28: 684 | H28: 684 | I28: 2734 | J28: 2744 | K28: 3490 | L28: 3505 | M28: 3622
B29: Other fixed assets | C29: 458 | D29: 117 | E29: 138 | F29: 212 | G29: 234 | H29: 663 | I29: 716 | J29: 719 | K29: 786 | L29: 841 | M29: 967
B30: Gross Block | C30: 23361 | D30: 16176 | E30: 18094 | F30: 19920 | G30: 24090 | H30: 27965 | I30: 31088 | J30: 33435 | K30: 36608 | L30: 40189 | M30: 33638
B31: Accumulated Depreciation | C31: 8057 | D31: 1069 | E31: 2201 | F31: 3396 | G31: 4716 | H31: 6252 | I31: 7790 | J31: 9204 | K31: 10757 | L31: 12368 | M31: 11683
B32: Net Block | C32: =C30-C31 -> 15304 | D32: =D30-D31 -> 15107 | E32: =E30-E31 -> 15893 | F32: =F30-F31 -> 16524 | G32: =G30-G31 -> 19374 | H32: =H30-H31 -> 21713 | I32: =I30-I31 -> 23298 | J32: =J30-J31 -> 24231 | ... M32: =M30-M31 -> 21955
B34: CWIP | C34: 2700 | D34: 2560 | E34: 3730 | F34: 5508 | G34: 4136 | H34: 3256 | I34: 4011 | J34: 3226 | K34: 3003 | L34: 2861 | M34: 1091
B35: Investments | C35: 6943 | D35: 11748 | E35: 17581 | F35: 22053 | G35: 25043 | H35: 28663 | I35: 24871 | J35: 24841 | K35: 29415 | L35: 31114 | M35: 34720
B37: Other Assets -
B38: Inventories | C38: 8587 | D38: 9062 | E38: 8116 | F38: 7495 | G38: 7860 | H38: 8879 | I38: 10397 | J38: 10864 | K38: 11771 | L38: 14153 | M38: 15638
B39: Trade receivables | C39: 1982 | D39: 1917 | E39: 2474 | F39: 2682 | G39: 4035 | H39: 2562 | I39: 2502 | J39: 2462 | K39: 2956 | L39: 4026 | M39: 4720
B40: Cash Equivalents | C40: 7896 | D40: 6063 | E40: 2967 | F40: 2900 | G40: 4152 | H40: 7277 | I40: 4659 | J40: 4654 | K40: 4880 | L40: 7218 | M40: 4012
B41: Loans n Advances | C41: 150 | D41: 14 | E41: 7 | F41: 74 | G41: 67 | H41: 6 | I41: 7 | J41: 11 | K41: 13 | L41: 31 | M41: 10
B42: Other asset items | C42: 2391 | D42: 5180 | E42: 5129 | F42: 7004 | G42: 7071 | H42: 4952 | I42: 4015 | J42: 6906 | K42: 7941 | L42: 4531 | M42: 5858
B43: Total Assets | C43: 45952 | D43: 51651 | E43: 55898 | F43: 64241 | G43: 71739 | H43: 77311 | I43: 73761 | J43: 77196 | K43: 85831 | L43: 91754 | M43: 88003
B47: Cash Flow Statement
B48: Cash from Operating Activity - | C48: 9843 | D48: 9799 | E48: 10627 | F48: 13169 | G48: 12583 | H48: 14690 | I48: 12527 | J48: 15776 | K48: 18878 | L48: 17179 | M48: 17627
B49: Profit from operations | C49: 14261 | D49: 15154 | E49: 16075 | F49: 17433 | G49: 18862 | H49: 19416 | I49: 17326 | J49: 20857 | K49: 26052 | L49: 26635 | M49: 26719
B50: Receivables | C50: 558 | D50: -207 | E50: -870 | F50: -964 | G50: -755 | H50: 1411 | I50: -66 | J50: -732 | K50: -884 | L50: -934 | M50: -1023
...

Sheet Beta Regression
B2: Regression Beta - 2 Years Daily
B4: ITC Weekly Returns | F4: Nifty Returns | I4: Drifted Beta
B6: Date | C6: Closing Price | D6: Return | F6: Closing Price | G6: Return | I6: Levered Raw Beta | J6: =M10 -> 0.59392765
B7: 45846.229 | C7: 417.2 | D7: 0 | F7: 25522.5 | G7: 0 | I7: Raw Beta Weight | J7: 0.75 | L7: Beta 1 | M7: =SLOPE(D8:D248,G8:G248) -> 0.59391069
B8: 45847.229 | C8: 419.45 | D8: =C8/C7 - 1 -> 0.0053930968 | F8: 25476.1 | G8: =F8/F7-1 -> -0.0018180037 | L8: Beta 2 | M8: =_xlfn.COVARIANCE.S(D7:D248,G7:G248)/_xlfn.VAR.S(G7:G248) -> 0.59392765
B9: 45848.229 | C9: 416.85 | D9: =C9/C8 - 1 -> -0.0061985934 | F9: 25355.25 | G9: =F9/F8-1 -> -0.0047436617 | I9: Market Beta | J9: 1
B10: 45849.229 | C10: 416.8 | D10: =C10/C9 - 1 -> -0.00011994722 | F10: 25149.85 | G10: =F10/F9-1 -> -0.0081008864 | I10: Market Beta Weight | J10: 0.25 | L10: Beta - Reg | M10: =N32 -> 0.59392765
B11: 45852.229 | C11: 419.4 | D11: =C11/C10 - 1 -> 0.0062380038 | F11: 25082.3 | G11: =F11/F10-1 -> -0.0026859007
B12: 45853.229 | C12: 422.1 | D12: =C12/C11 - 1 -> 0.0064377682 | F12: 25195.8 | G12: =F12/F11-1 -> 0.0045251034 | I12: Adjusted Beta | J12: =J6*J7+J9*J10 -> 0.69544574
B13: 45854.229 | C13: 424.6 | D13: =C13/C12 - 1 -> 0.0059227671 | F13: 25212.05 | G13: =F13/F12-1 -> 0.00064494876
B14: 45855.229 | C14: 423.95 | D14: =C14/C13 - 1 -> -0.0015308526 | F14: 25111.45 | G14: =F14/F13-1 -> -0.0039901555
B15: 45856.229 | C15: 422.75 | D15: =C15/C14 - 1 -> -0.0028305225 | F15: 24968.4 | G15: =F15/F14-1 -> -0.0056966045 | M15: SUMMARY OUTPUT
B16: 45859.229 | C16: 420.1 | D16: =C16/C15 - 1 -> -0.0062684802 | F16: 25090.7 | G16: =F16/F15-1 -> 0.0048981913
B17: 45860.229 | C17: 416 | D17: =C17/C16 - 1 -> -0.0097595811 | F17: 25060.9 | G17: =F17/F16-1 -> -0.0011876911 | M17: Regression Statistics
B18: 45861.229 | C18: 414.95 | D18: =C18/C17 - 1 -> -0.0025240385 | F18: 25219.9 | G18: =F18/F17-1 -> 0.0063445447 | M18: Multiple R | N18: 0.39326212
B19: 45862.229 | C19: 409.95 | D19: =C19/C18 - 1 -> -0.012049645 | F19: 25062.1 | G19: =F19/F18-1 -> -0.0062569637 | M19: R Square | N19: 0.15465509
B20: 45863.229 | C20: 409.4 | D20: =C20/C19 - 1 -> -0.001341627 | F20: 24837 | G20: =F20/F19-1 -> -0.0089816895 | M20: Adjusted R Square | N20: 0.15113282
B21: 45866.229 | C21: 409.9 | D21: =C21/C20 - 1 -> 0.0012212995 | F21: 24680.9 | G21: =F21/F20-1 -> -0.0062849781 | M21: Standard Error | N21: 0.011573224
B22: 45867.229 | C22: 408.45 | D22: =C22/C21 - 1 -> -0.0035374482 | F22: 24821.1 | G22: =F22/F21-1 -> 0.005680506 | M22: Observations | N22: 242
B23: 45868.229 | C23: 407.6 | D23: =C23/C22 - 1 -> -0.0020810381 | F23: 24855.05 | G23: =F23/F22-1 -> 0.0013677879
B24: 45869.229 | C24: 411.95 | D24: =C24/C23 - 1 -> 0.010672228 | F24: 24768.35 | G24: =F24/F23-1 -> -0.0034882247 | M24: ANOVA
B25: 45870.229 | C25: 416.45 | D25: =C25/C24 - 1 -> 0.010923656 | F25: 24565.35 | G25: =F25/F24-1 -> -0.0081959436 | N25: df | O25: SS | P25: MS | Q25: F | R25: Significance F
B26: 45873.229 | C26: 416.85 | D26: =C26/C25 - 1 -> 0.00096049946 | F26: 24722.75 | G26: =F26/F25-1 -> 0.006407399 | M26: Regression | N26: 1 | O26: 0.0058809878 | P26: 0.0058809878 | Q26: 43.907785 | R26: 2.2462593e-10
B27: 45874.229 | C27: 414.15 | D27: =C27/C26 - 1 -> -0.0064771501 | F27: 24649.55 | G27: =F27/F26-1 -> -0.0029608357 | M27: Residual | N27: 240 | O27: 0.032145486 | P27: 0.00013393952
B28: 45875.229 | C28: 412 | D28: =C28/C27 - 1 -> -0.0051913558 | F28: 24574.2 | G28: =F28/F27-1 -> -0.0030568509 | M28: Total | N28: 241 | O28: 0.038026474
B29: 45876.229 | C29: 413.6 | D29: =C29/C28 - 1 -> 0.0038834951 | F29: 24596.15 | G29: =F29/F28-1 -> 0.00089321321
B30: 45877.229 | C30: 414.5 | D30: =C30/C29 - 1 -> 0.0021760155 | F30: 24363.3 | G30: =F30/F29-1 -> -0.0094669288 | N30: Coefficients | O30: Standard Error | P30: t Stat | Q30: P-value | R30: Lower 95% | S30: Upper 95% | T30: Lower 95.0% | U30: Upper 95.0%
B31: 45880.229 | C31: 416.85 | D31: =C31/C30 - 1 -> 0.0056694813 | F31: 24585.05 | G31: =F31/F30-1 -> 0.0091018048 | M31: Intercept | N31: -0.0012876605 | O31: 0.00074421313 | P31: -1.7302308 | Q31: 0.084874537 | R31: -0.0027536841 | S31: 0.00017836324 | T31: -0.0027536841 | U31: 0.00017836324
B32: 45881.229 | C32: 416.35 | D32: =C32/C31 - 1 -> -0.0011994722 | F32: 24487.4 | G32: =F32/F31-1 -> -0.003971926 | M32: Return | N32: 0.59392765 | O32: 0.089631937 | P32: 6.6262949 | Q32: 2.2462593e-10 | R32: 0.41736191 | S32: 0.77049339 | T32: 0.41736191 | U32: 0.77049339
B33: 45882.229 | C33: 414.1 | D33: =C33/C32 - 1 -> -0.0054041071 | F33: 24619.35 | G33: =F33/F32-1 -> 0.0053884855
B34: 45883.229 | C34: 411.45 | D34: =C34/C33 - 1 -> -0.0063994204 | F34: 24631.3 | G34: =F34/F33-1 -> 0.00048539056
B35: 45887.229 | C35: 406.3 | D35: =C35/C34 - 1 -> -0.012516709 | F35: 24876.95 | G35: =F35/F34-1 -> 0.009973083
B36: 45888.229 | C36: 409.1 | D36: =C36/C35 - 1 -> 0.0068914595 | F36: 24980.65 | G36: =F36/F35-1 -> 0.0041685174
B37: 45889.229 | C37: 406.05 | D37: =C37/C36 - 1 -> -0.0074553899 | F37: 25050.55 | G37: =F37/F36-1 -> 0.0027981658
B38: 45890.229 | C38: 405.55 | D38: =C38/C37 - 1 -> -0.0012313754 | F38: 25083.75 | G38: =F38/F37-1 -> 0.0013253202
B39: 45891.229 | C39: 398.3 | D39: =C39/C38 - 1 -> -0.017876957 | F39: 24870.1 | G39: =F39/F38-1 -> -0.0085174665
B40: 45894.229 | C40: 399.35 | D40: =C40/C39 - 1 -> 0.0026362039 | F40: 24967.75 | G40: =F40/F39-1 -> 0.0039264016
B41: 45895.229 | C41: 403.35 | D41: =C41/C40 - 1 -> 0.010016276 | F41: 24712.05 | G41: =F41/F40-1 -> -0.010241211
B42: 45897.229 | C42: 400.9 | D42: =C42/C41 - 1 -> -0.0060741292 | F42: 24500.9 | G42: =F42/F41-1 -> -0.0085444146
B43: 45898.229 | C43: 409.75 | D43: =C43/C42 - 1 -> 0.022075331 | F43: 24426.85 | G43: =F43/F42-1 -> -0.003022338
...

Sheet Rm 
B2: Return on Markets (Nifty 50)
B3: Years | C3: Annual
B4: 2025 | C4: 0.1051
B5: 2024 | C5: 0.0875 | E5: Average Return | F5: =AVERAGE(C4:C23) -> 0.15127
B6: 2023 | C6: 0.1942 | E6: Dividend Yield | F6: 0.013
B7: 2022 | C7: 0.0432 | F7: =SUM(F5:F6) -> 0.16427
B8: 2021 | C8: 0.2412
B9: 2020 | C9: 0.149
B10: 2019 | C10: 0.1202
B11: 2018 | C11: 0.0315
B12: 2017 | C12: 0.2865
B13: 2016 | C13: 0.0301
B14: 2015 | C14: -0.0406
B15: 2014 | C15: 0.3139
B16: 2013 | C16: 0.0676
B17: 2012 | C17: 0.277
B18: 2011 | C18: -0.2462
B19: 2010 | C19: 0.1795
... B23: 2006 | C23: 0.3983

Sheet Intrinsic Growth
B3: Calculation of ROIC | G3: 43891 | H3: 44256 | I3: 44621 | J3: 44986 | K3: 45352 | L3: 45717
B5: Current Assets
B6: Inventories | G6: ='Raw FS '!H38 -> 8879 | H6: ='Raw FS '!I38 -> 10397 | I6: ='Raw FS '!J38 -> 10864 | J6: ='Raw FS '!K38 -> 11771 | K6: ='Raw FS '!L38 -> 14153 | L6: ='Raw FS '!M38 -> 15638
B7: Trade receivables | G7: ='Raw FS '!H39 -> 2562 | H7: ='Raw FS '!I39 -> 2502 | I7: ='Raw FS '!J39 -> 2462 | J7: ='Raw FS '!K39 -> 2956 | K7: ='Raw FS '!L39 -> 4026 | L7: ='Raw FS '!M39 -> 4720
B8: Loans n Advances | G8: ='Raw FS '!H41 -> 6 | H8: ='Raw FS '!I41 -> 7 | I8: ='Raw FS '!J41 -> 11 | J8: ='Raw FS '!K41 -> 13 | K8: ='Raw FS '!L41 -> 31 | L8: ='Raw FS '!M41 -> 10
B9: Other asset items | G9: ='Raw FS '!H42 -> 4952 | H9: ='Raw FS '!I42 -> 4015 | I9: ='Raw FS '!J42 -> 6906 | J9: ='Raw FS '!K42 -> 7941 | K9: ='Raw FS '!L42 -> 4531 | L9: ='Raw FS '!M42 -> 5858
B10: Total Current Assets | G10: =SUM(G6:G9) -> 16399 | H10: =SUM(H6:H9) -> 16921 | I10: =SUM(I6:I9) -> 20243 | J10: =SUM(J6:J9) -> 22681 | K10: =SUM(K6:K9) -> 22741 | L10: =SUM(L6:L9) -> 26226
B12: Current Liabilities
B13: Trade Payables | G13: ='Raw FS '!H15 -> 3630 | H13: ='Raw FS '!I15 -> 4319 | I13: ='Raw FS '!J15 -> 4417 | J13: ='Raw FS '!K15 -> 4659 | K13: ='Raw FS '!L15 -> 4798 | L13: ='Raw FS '!M15 -> 4807
B14: Advance from Customers | G14: ='Raw FS '!H16 -> 703 | H14: ='Raw FS '!I16 -> 811 | I14: ='Raw FS '!J16 -> 1278 | J14: ='Raw FS '!K16 -> 1295 | K14: ='Raw FS '!L16 -> 886 | L14: ='Raw FS '!M16 -> 1264
B15: Other liability items | G15: ='Raw FS '!H17 -> 7050 | H15: ='Raw FS '!I17 -> 7666 | I15: ='Raw FS '!J17 -> 8429 | J15: ='Raw FS '!K17 -> 10032 | K15: ='Raw FS '!L17 -> 10877 | L15: ='Raw FS '!M17 -> 11249
B16: Total Current Liabilities | G16: =SUM(G13:G15) -> 11383 | H16: =SUM(H13:H15) -> 12796 | I16: =SUM(I13:I15) -> 14124 | J16: =SUM(J13:J15) -> 15986 | K16: =SUM(K13:K15) -> 16561 | L16: =SUM(L13:L15) -> 17320
B18: Net Working Capital | G18: =G10-G16 -> 5016 | H18: =H10-H16 -> 4125 | I18: =I10-I16 -> 6119 | J18: =J10-J16 -> 6695 | K18: =K10-K16 -> 6180 | L18: =L10-L16 -> 8906
B20: Non Current Assets
B21: Land | G21: ='Raw FS '!H21 -> 2797 | H21: ='Raw FS '!I21 -> 2889 | I21: ='Raw FS '!J21 -> 2829 | J21: ='Raw FS '!K21 -> 2830 | K21: ='Raw FS '!L21 -> 2865 | L21: ='Raw FS '!M21 -> 1588
B22: Building | G22: ='Raw FS '!H22 -> 8161 | H22: ='Raw FS '!I22 -> 8387 | I22: ='Raw FS '!J22 -> 9100 | J22: ='Raw FS '!K22 -> 9789 | K22: ='Raw FS '!L22 -> 10944 | L22: ='Raw FS '!M22 -> 7550
B23: Plant Machinery | G23: ='Raw FS '!H23 -> 14625 | H23: ='Raw FS '!I23 -> 15307 | I23: ='Raw FS '!J23 -> 16912 | J23: ='Raw FS '!K23 -> 18480 | K23: ='Raw FS '!L23 -> 20718 | L23: ='Raw FS '!M23 -> 19423
B24: Equipments | G24: ='Raw FS '!H24 -> 40 | H24: ='Raw FS '!I24 -> 41 | I24: ='Raw FS '!J24 -> 44 | J24: ='Raw FS '!K24 -> 44 | K24: ='Raw FS '!L24 -> 53 | L24: ='Raw FS '!M24 -> 63
B25: Furniture n fittings | G25: ='Raw FS '!H25 -> 810 | H25: ='Raw FS '!I25 -> 833 | I25: ='Raw FS '!J25 -> 907 | J25: ='Raw FS '!K25 -> 1000 | K25: ='Raw FS '!L25 -> 1068 | L25: ='Raw FS '!M25 -> 282
B26: Railway sidings | G26: ='Raw FS '!H26 -> 2 | H26: ='Raw FS '!I26 -> 2 | I26: ='Raw FS '!J26 -> 2 | J26: ='Raw FS '!K26 -> 2 | K26: ='Raw FS '!L26 -> 2 | L26: ='Raw FS '!M26 -> 2
B27: Vehicles | G27: ='Raw FS '!H27 -> 184 | H27: ='Raw FS '!I27 -> 180 | I27: ='Raw FS '!J27 -> 179 | J27: ='Raw FS '!K27 -> 189 | K27: ='Raw FS '!L27 -> 192 | L27: ='Raw FS '!M27 -> 141
B28: Intangible Assets | G28: ='Raw FS '!H28 -> 684 | H28: ='Raw FS '!I28 -> 2734 | I28: ='Raw FS '!J28 -> 2744 | J28: ='Raw FS '!K28 -> 3490 | K28: ='Raw FS '!L28 -> 3505 | L28: ='Raw FS '!M28 -> 3622
B29: Other fixed assets | G29: ='Raw FS '!H29 -> 663 | H29: ='Raw FS '!I29 -> 716 | I29: ='Raw FS '!J29 -> 719 | J29: ='Raw FS '!K29 -> 786 | K29: ='Raw FS '!L29 -> 841 | L29: ='Raw FS '!M29 -> 967
B30: Gross Block | G30: =SUM(G21:G29) -> 27966 | H30: =SUM(H21:H29) -> 31089 | I30: =SUM(I21:I29) -> 33436 | J30: =SUM(J21:J29) -> 36610 | K30: =SUM(K21:K29) -> 40188 | L30: =SUM(L21:L29) -> 33638
B31: Accumulated Depriciation | G31: =-'Raw FS '!H31 -> -6252 | H31: =-'Raw FS '!I31 -> -7790 | I31: =-'Raw FS '!J31 -> -9204 | J31: =-'Raw FS '!K31 -> -10757 | K31: =-'Raw FS '!L31 -> -12368 | L31: =-'Raw FS '!M31 -> -11683
B32: Net Fixed Income | G32: =SUM(G30:G31) -> 21714 | H32: =SUM(H30:H31) -> 23299 | I32: =SUM(I30:I31) -> 24232 | J32: =SUM(J30:J31) -> 25853 | K32: =SUM(K30:K31) -> 27820 | L32: =SUM(L30:L31) -> 21955
B34: Invested Capital | G34: =G32+G18 -> 26730 | H34: =H32+H18 -> 27424 | I34: =I32+I18 -> 30351 | J34: =J32+J18 -> 32548 | K34: =K32+K18 -> 34000 | L34: =L32+L18 -> 30861
B35: EBIT | G35: =HistoricalFS!C18-HistoricalFS!C24 -> 14316.72 | H35: =HistoricalFS!D18-HistoricalFS!D24 -> 15284.31 | I35: =HistoricalFS!E18-HistoricalFS!E24 -> 17140.78 | J35: =HistoricalFS!F18-HistoricalFS!F24 -> 17698.63 | K35: =HistoricalFS!G18-HistoricalFS!G24 -> 15419.19 | L35: =HistoricalFS!H18-HistoricalFS!H24 -> 18890.74
B37: ROIC | G37: =G35/G34 -> 0.53560494 | H37: =H35/H34 -> 0.55733336 | I37: =I35/I34 -> 0.56475174 | J37: =J35/J34 -> 0.54377012 | K37: =K35/K34 -> 0.45350559 | L37: =L35/L34 -> 0.61212339
B39: Calculation of Reinvestment Rate | G39: 43891 | H39: 44256 | I39: 44621 | J39: 44986 | K39: 45352 | L39: 45717
B41: Net Capex | G41: =-SUM('Raw FS '!H56:H57) -> 2414 | H41: =-SUM('Raw FS '!I56:I57) -> 1834 | I41: =-SUM('Raw FS '!J56:J57) -> 2009 | J41: =-SUM('Raw FS '!K56:K57) -> 2694 | K41: =-SUM('Raw FS '!L56:L57) -> 3456 | L41: =-SUM('Raw FS '!M56:M57) -> 2104
B42: Change in Working Capital | H42: =H18-G18 -> -891 | I42: =I18-H18 -> 1994 | J42: =J18-I18 -> 576 | K42: =K18-J18 -> -515 | L42: =L18-K18 -> 2726
B44: EBIT | G44: =G35 -> 14316.72 | H44: =H35 -> 15284.31 | I44: =I35 -> 17140.78 | J44: =J35 -> 17698.63 | K44: =K35 -> 15419.19 | L44: =L35 -> 18890.74
B45: Marginal Tax Rate | G45: 0.25 | H45: 0.25 | I45: 0.25 | J45: 0.25 | K45: 0.25 | L45: 0.25
B46: EBIT(1-T) | G46: =G44*(1-G45) -> 10737.54 | H46: =H44*(1-H45) -> 11463.233 | I46: =I44*(1-I45) -> 12855.585 | J46: =J44*(1-J45) -> 13273.972 | K46: =K44*(1-K45) -> 11564.392 | L46: =L44*(1-L45) -> 14168.055
B48: Reinvestment | H48: =SUM(H41:H42) -> 943 | I48: =SUM(I41:I42) -> 4003 | J48: =SUM(J41:J42) -> 3270 | K48: =SUM(K41:K42) -> 2941 | L48: =SUM(L41:L42) -> 4830
B50: Reinvestment Rate | H50: =H48/H46 -> 0.082263009 | I50: =I48/I46 -> 0.31138217 | J50: =J48/J46 -> 0.24634675 | K50: =K48/K46 -> 0.25431513 | L50: =L48/L46 -> 0.34090777
J52: 4 Year Average | K52: =AVERAGE(I50:L50) -> 0.28823796
J53: 4 Year Median | K53: =MEDIAN(I50:L50) -> 0.28284865
B55: Calculation of Growth Rate | G55: 43891 | H55: 44256 | I55: 44621 | J55: 44986 | K55: 45352 | L55: 45717
...

Sheet WACC
B2: Weighted Average Cost of Capital
B4: Peer Comps
G5: Debt/ | H5: Debt/ | I5: Levered | J5: Unlevered
B6: Name | C6: Country | D6: Total Debt | E6: Total Equity | F6: Tax Rate 1 | G6: Equity | H6: Capital | I6: Beta 2 | J6: Beta 3
B8: Hind. Unilever | C8: India | D8: 2185.2 | E8: 513432.69 | F8: 0.25 | G8: =D8/E8 -> 0.0042560593 | H8: =D8/(E8+D8) -> 0.0042380221 | I8: 0.564 | J8: =I8/(1+(1-F8)*G8) -> 0.56220542
B9: ITC | C9: India | D9: 289.85 | E9: 363166.62 | F9: 0.25 | G9: =D9/E9 -> 0.00079811851 | H9: =D9/(E9+D9) -> 0.00079748202 | I9: 0.491 | J9: =I9/(1+(1-F9)*G9) -> 0.49070627
B10: Hindustan Foods | C10: India | D10: 560 | E10: 6785.09 | F10: 0.25 | G10: =D10/E10 -> 0.082533909 | H10: =D10/(E10+D10) -> 0.076241408 | I10: 0.977 | J10: =I10/(1+(1-F10)*G10) -> 0.92004859
B11: Godavari Bioref. | C11: India | D11: 294.65 | E11: 1507.92 | F11: 0.25 | G11: =D11/E11 -> 0.19540161 | H11: =D11/(E11+D11) -> 0.16346106 | I11: 0.452 | J11: =I11/(1+(1-F11)*G11) -> 0.39422574
B12: Davangere Sugar | C12: India | D12: 3.61 | E12: 516.23 | F12: 0.25 | G12: =D12/E12 -> 0.006993007 | H12: =D12/(E12+D12) -> 0.0069444444 | I12: 0.5 | J12: =I12/(1+(1-F12)*G12) -> 0.4973913
E14: Average | F14: =AVERAGE(F8:F12) -> 0.25 | G14: =AVERAGE(G8:G12) -> 0.057996541 | H14: =AVERAGE(H8:H12) -> 0.050336483 | I14: =AVERAGE(I8:I12) -> 0.5968 | J14: =AVERAGE(J8:J12) -> 0.57291546
E15: Median | F15: =AVERAGE(F9:F13) -> 0.25 | G15: =AVERAGE(G9:G13) -> 0.071431662 | H15: =AVERAGE(H9:H13) -> 0.061861098 | I15: =MEDIAN(I8:I12) -> 0.5 | J15: =MEDIAN(J8:J12) -> 0.4973913
B18: Cost of Debt | G18: Cost of Equity
B20: Pre tax cost of debt | D20: =29/D9 -> 0.10005175 | G20: Risk Free Rate | J20: 0.0664
B21: Tax Rate | D21: =F12 -> 0.25 | G21: Equity Risk Premium | J21: =-IFERROR(WACC!F7-WACC!J20,0) -> 0.0664
B22: After tax cost of debt | D22: =D20*(1-D21) -> 0.075038813 | G22: Levered Beta 4 | J22: =J31 -> 0.52035856
G23: Cost of Equity | J23: =J20+(J21*J22) -> 0.10095181
B26: Capital Structure | G26: Levered Beta
D28: Current | E28: Target | G28: Comps Median Unlevered Beta | J28: =J15 -> 0.4973913
B29: Total Debt | C29: =D9 -> 289.85 | D29: =C29/C31 -> 0.00079748202 | E29: =G14 -> 0.057996541 | G29: Target Debt/ Equity | J29: =E33 -> 0.061567228
B30: Market Capitalization | C30: =E9 -> 363166.62 | D30: =C30/C31 -> 0.99920252 | E30: =E31-E29 -> 0.94200346 | G30: Tax Rate | J30: =F14 -> 0.25
B31: Total Capitalization | C31: =C29+C30 -> 363456.47 | D31: =C31/C31 -> 1 | E31: =D31 -> 1 | G31: Levered Beta | J31: =J28*(1+(1-J30)*J29) -> 0.52035856
B33: Debt / Equity | D33: =C29/C30 -> 0.00079811851 | E33: =E29/E30 -> 0.061567228 | G33: Weighted Average Cost of Capital
B35: 1. Tax Rate considered as Marginal Tax Rate for the country | G35: Cost of Equity | J35: =J23 -> 0.10095181
B36: 2. Levered Beta is based on 5 year monthly data | G36: Equity Weight | J36: =E30 -> 0.94200346
B37: 3. Unlevered Beta = Levered Beta/(1+(1-Tax Rate) x Debt/Equity)
B38: 3. Levered Beta = Unlevered Beta/(1+(1-Tax Rate) x Debt/Equity) | G38: Cost of Debt | J38: =D22 -> 0.075038813
G39: Debt Weight | J39: =E29 -> 0.057996541
G41: WACC | J41: =J35*J36+J38*J39 -> 0.099448944

Sheet DCF
B2: Calculation of PV of FCFF | E2: 46082 | F2: =E2+366 -> 46448 | G2: =F2+366 -> 46814 | H2: =G2+366 -> 47180 | I2: =H2+366 -> 47546 | J2: =I2+366 -> 47912
B4: EBIT (Operational Income ) | E4: ='Data Sheet'!K34-'Data Sheet'!K26 -> 27789.88 | F4: =E4*(1+$D$14) -> 31871.218 | G4: =F4*(1+$D$14) -> 36551.957 | H4: =G4*(1+$D$14) -> 41920.13 | I4: =H4*(1+$D$14) -> 48076.695 | J4: =I4*(1+$D$14) -> 55137.439
B5: Tax Rate | E5: 0.25 | F5: 0.25 | G5: 0.25 | H5: 0.25 | I5: 0.25 | J5: 0.25
B6: EBIT(1-T) | E6: =E4*(1-E5) -> 20842.41 | F6: =F4*(1-F5) -> 23903.413 | G6: =G4*(1-G5) -> 27413.968 | H6: =H4*(1-H5) -> 31440.098 | I6: =I4*(1-I5) -> 36057.521 | J6: =J4*(1-J5) -> 41353.079
B7: Less: Reinvestment rate | E7: ='Intrinsic Growth'!$K$53 -> 0.28284865 | F7: =E$7+($J$7-$E$7)/5 -> 0.28627892 | G7: =F$7+($J$7-$E$7)/5 -> 0.28970919 | H7: =G$7+($J$7-$E$7)/5 -> 0.29313946 | I7: =H$7+($J$7-$E$7)/5 -> 0.29656973 | J7: 0.3
B8: Free Cash Flow to Firm | E8: =E6*(1-E7) -> 14947.162 | F8: =F6*(1-F7) -> 17060.37 | G8: =G6*(1-G7) -> 19471.89 | H8: =H6*(1-H7) -> 22223.764 | I8: =I6*(1-I7) -> 25363.952 | J8: =J6*(1-J7) -> 28947.155
B9: Mid Year Convention | F9: 0.5 | G9: =F9+1 -> 1.5 | H9: =G9+1 -> 2.5 | I9: =H9+1 -> 3.5 | J9: =I9+1 -> 4.5
B10: Discounting Factor | F10: =1/(1+$D$16)^F9 -> 0.9537015 | G10: =1/(1+$D$16)^G9 -> 0.86743592 | H10: =1/(1+$D$16)^H9 -> 0.78897335 | I10: =1/(1+$D$16)^I9 -> 0.71760799 | J10: =1/(1+$D$16)^J9 -> 0.65269788
B12: PV of FCFF | F12: =F8*F10 -> 16270.5 | G12: =G8*G10 -> 16890.616 | H12: =H8*H10 -> 17533.958 | I12: =I8*I10 -> 18201.375 | J12: =J8*J10 -> 18893.747
B14: Expected Growth | D14: ='Intrinsic Growth'!K63 -> 0.14686417
B15: Terminal Growth | D15: 0.03
B16: WACC | D16: =WACC!J41 -> 0.099448944
B18: Calculation of Terminal Value | F18: Sensitivity Analysis
F19: =D38 -> 322.2153 | G19: 0.06 | H19: 0.08 | I19: 0.0994 | J19: 0.12
B20: FCFF(n+1) | D20: =J8*(1+D14) -> 33198.455 | F20: 0.02 | G20: 505.54868 | H20: 361.43135 | I20: 291.00626 | J20: 246.13749
B21: WACC | D21: =D16 -> 0.099448944 | F21: =F20+0.01 -> 0.03 | G21: 649.66602 | H21: 419.07829 | I21: 322.39092 | J21: 265.35313
B22: Terminal Growth Rate | D22: =D15 -> 0.03 | F22: =F21+0.01 -> 0.04 | G22: 937.90068 | H22: 505.54868 | I22: 364.34281 | J22: 289.37269
F23: =F22+0.01 -> 0.05 | G23: 1802.6047 | H23: 649.66602 | I23: 423.27928 | J23: 320.25497
B24: Terminal Value of FCFF | D24: =D20/(D21-D22) -> 478026.78
B26: Calculation of Equity Value per Share
B28: PV of FCFF | D28: =SUM(F12:J12) -> 87790.196
B29: PV of Terminal Value | D29: =D24*J10 -> 312007.07
B30: Value of Operating Assets (Enterprise Value ) | D30: =SUM(D28:D29) -> 399797.26
B32: Add: Cash | D32: ='Data Sheet'!J69 -> 4012.36
B33: Less: Debt | D33: ='Raw FS '!M8+'Raw FS '!M9 -> 91
B35: Equity Value | D35: =D30+D32-D33 -> 403718.62
B36: No of Shares | D36: ='Data Sheet'!B6 -> 1252.9468
B38: Equity Value per Share | D38: =D35/D36 -> 322.2153
B40: Share Price | D40: 292.5
B41: Discounted/Premium | D41: =D40/D38 -> 0.90777811
D43: Trading at Discount

Sheet Comparable Comps 
B2: Comparable Company Valuation | C2: (in crores)
C4: Market Data | I4: Financials | M4: Valuation
C5: Share | D5: Share | E5: Equity | G5: Enterprise
B6: Company | C6: Price | D6: Outstanding | E6: Value | F6: Net Debt | G6: Value | I6: Revenue | J6: EBITDA | K6: Net Income | M6: EV/Revenue | N6: EV/EBITDA | O6: P/E
B7: Hind. Unilever | C7: =[1]Sheet2!D3 -> 2194.6 | D7: =[1]Sheet2!G3 -> 234.96 | E7: =D7*C7 -> 515643.22 | F7: =[1]Sheet2!F3-[1]Sheet2!H3 -> -1770 | G7: =E7+F7 -> 513873.22 | I7: =[1]Sheet2!E3 -> 64468 | J7: =[1]Sheet2!J3+[1]Sheet2!K3 -> 15790 | K7: =[1]Sheet2!L3 -> 15059 | M7: =G7/I7 -> 7.9709812 | N7: =G7/J7 -> 32.544219 | O7: =E7/K7 -> 34.241531
B8: ITC | C8: =[1]Sheet2!D4 -> 292.5 | D8: =[1]Sheet2!G4 -> 1252.95 | E8: =D8*C8 -> 366487.88 | F8: =[1]Sheet2!F4-[1]Sheet2!H4 -> -609.73 | G8: =E8+F8 -> 365878.15 | I8: =[1]Sheet2!E4 -> 78868.4 | J8: =[1]Sheet2!J4+[1]Sheet2!K4 -> 30120.79 | K8: =[1]Sheet2!L4 -> 21018.15 | M8: =G8/I8 -> 4.6390968 | N8: =G8/J8 -> 12.14703 | O8: =E8/K8 -> 17.436733
B9: Nestle India | C9: =[1]Sheet2!D5 -> 1414.8 | D9: =[1]Sheet2!G5 -> 192.83 | E9: =D9*C9 -> 272815.88 | F9: =[1]Sheet2!F5-[1]Sheet2!H5 -> -896.71 | G9: =E9+F9 -> 271919.17 | I9: =[1]Sheet2!E5 -> 23154.6 | J9: =[1]Sheet2!J5+[1]Sheet2!K5 -> 5342.42 | K9: =[1]Sheet2!L5 -> 3544.6 | M9: =G9/I9 -> 11.743635 | N9: =G9/J9 -> 50.898127 | O9: =E9/K9 -> 76.966621
B10: Varun Beverages | C10: =[1]Sheet2!D6 -> 529.5 | D10: =[1]Sheet2!G6 -> 338.23 | E10: =D10*C10 -> 179092.79 | F10: =[1]Sheet2!F6-[1]Sheet2!H6 -> 509.69 | G10: =E10+F10 -> 179602.48 | I10: =[1]Sheet2!E6 -> 22692.63 | J10: =[1]Sheet2!J6+[1]Sheet2!K6 -> 5672.75 | K10: =[1]Sheet2!L6 -> 3209.4 | M10: =G10/I10 -> 7.9145729 | N10: =G10/J10 -> 31.660566 | O10: =E10/K10 -> 55.802575
B11: Britannia Inds. | C11: =[1]Sheet2!D7 -> 5195 | D11: =[1]Sheet2!G7 -> 24.09 | E11: =D11*C11 -> 125147.55 | F11: =[1]Sheet2!F7-[1]Sheet2!H7 -> 1027.84 | G11: =E11+F11 -> 126175.39 | I11: =[1]Sheet2!E7 -> 19151.59 | J11: =[1]Sheet2!J7+[1]Sheet2!K7 -> 3738.37 | K11: =[1]Sheet2!L7 -> 2537.01 | M11: =G11/I11 -> 6.5882462 | N11: =G11/J11 -> 33.751445 | O11: =E11/K11 -> 49.328757
B12: Tata Consumer | C12: =[1]Sheet2!D8 -> 1111.5 | D12: =[1]Sheet2!G8 -> 98.96 | E12: =D12*C12 -> 109994.04 | F12: =[1]Sheet2!F8-[1]Sheet2!H8 -> -600.98 | G12: =E12+F12 -> 109393.06 | I12: =[1]Sheet2!E8 -> 20290.43 | J12: =[1]Sheet2!J8+[1]Sheet2!K8 -> 2928 | K12: =[1]Sheet2!L8 -> 1546.8 | M12: =G12/I12 -> 5.3913623 | N12: =G12/J12 -> 37.361018 | O12: =E12/K12 -> 71.110706
B13: Marico | C13: =[1]Sheet2!D9 -> 817.05 | D13: =[1]Sheet2!G9 -> 129.84 | E13: =D13*C13 -> 106085.77 | F13: =[1]Sheet2!F9-[1]Sheet2!H9 -> 64 | G13: =E13+F13 -> 106149.77 | I13: =[1]Sheet2!E9 -> 13611 | J13: =[1]Sheet2!J9+[1]Sheet2!K9 -> 2532 | K13: =[1]Sheet2!L9 -> 1813 | M13: =G13/I13 -> 7.7988224 | N13: =G13/J13 -> 41.923291 | O13: =E13/K13 -> 58.513939
B14: Godrej Consumer | C14: =[1]Sheet2!D10 -> 1000.6 | D14: =[1]Sheet2!G10 -> 102.32 | E14: =D14*C14 -> 102381.39 | F14: =[1]Sheet2!F10-[1]Sheet2!H10 -> 3410.4 | G14: =E14+F14 -> 105791.79 | I14: =[1]Sheet2!E10 -> 15177.9 | J14: =[1]Sheet2!J10+[1]Sheet2!K10 -> 3422.41 | K14: =[1]Sheet2!L10 -> 1861.47 | M14: =G14/I14 -> 6.9701205 | N14: =G14/J14 -> 30.91149 | O14: =E14/K14 -> 55.000291
B15: United Spirits | C15: =[1]Sheet2!D11 -> 1320.5 | D15: =[1]Sheet2!G11 -> 72.74 | E15: =D15*C15 -> 96053.17 | F15: =[1]Sheet2!F11-[1]Sheet2!H11 -> -1564 | G15: =E15+F15 -> 94489.17 | I15: =[1]Sheet2!E11 -> 12467 | J15: =[1]Sheet2!J11+[1]Sheet2!K11 -> 2757 | K15: =[1]Sheet2!L11 -> 1838 | M15: =G15/I15 -> 7.5791425 | N15: =G15/J15 -> 34.272459 | O15: =E15/K15 -> 52.259614
B16: Dabur India | C16: =[1]Sheet2!D12 -> 423.5 | D16: =[1]Sheet2!G12 -> 177.4 | E16: =D16*C16 -> 75128.9 | F16: =[1]Sheet2!F12-[1]Sheet2!H12 -> 725.25 | G16: =E16+F16 -> 75854.15 | I16: =[1]Sheet2!E12 -> 13192.57 | J16: =[1]Sheet2!J12+[1]Sheet2!K12 -> 3049.81 | K16: =[1]Sheet2!L12 -> 1868.69 | M16: =G16/I16 -> 5.7497629 | N16: =G16/J16 -> 24.871763 | O16: =E16/K16 -> 40.204047
B18: High | M18: =MAX(M7:M16) -> 11.743635 | N18: =MAX(N7:N16) -> 50.898127 | O18: =MAX(O7:O16) -> 76.966621
B19: 75th percentile | M19: =QUARTILE(M7:M16,3) -> 7.8856353 | N19: =QUARTILE(N7:N16,3) -> 36.588878 | O19: =QUARTILE(O7:O16,3) -> 57.836098
B20: Average | M20: =AVERAGE(M7:M16) -> 7.2345743 | N20: =AVERAGE(N7:N16) -> 33.034141 | O20: =AVERAGE(O7:O16) -> 51.086481
B21: Median | M21: =MEDIAN(M7:M16) -> 7.2746315 | N21: =MEDIAN(N7:N16) -> 33.147832 | O21: =MEDIAN(O7:O16) -> 53.629952
B22: 25th percentile | M22: =QUARTILE(M7:M16,1) -> 5.9593838 | N22: =QUARTILE(N7:N16,1) -> 31.098759 | O22: =QUARTILE(O7:O16,1) -> 42.485224
B24: Sun Pharma.Inds. Comparable Valuation | M24: EV/Revenue | N24: EV/EBITDA | O24: P/E
B25: Implied Enterprise Value | M25: =M21*I8 -> 573738.55 | N25: =N21*J8 -> 998438.89 | O25: =O27+O26 -> 1126592.7
B26: Net Debt | M26: =$F$8 -> -609.73 | N26: =$F$8 -> -609.73 | O26: =$F$8 -> -609.73
B27: Implied Market Value | M27: =M25-M26 -> 574348.28 | N27: =N25-N26 -> 999048.62 | O27: =O21*K8 -> 1127202.4
B28: Shares Outstanding | M28: =$D$8 -> 1252.95 | N28: =$D$8 -> 1252.95 | O28: =$D$8 -> 1252.95
B29: Implied value per share | M29: =M27/M28 -> 458.39681 | N29: =N27/N28 -> 797.35713 | O29: =O27/O28 -> 899.63876
M31: =IF($C$8>M29,"Overvalued","Undervalued") -> Undervalued | N31: =IF($C$8>N29,"Overvalued","Undervalued") -> Undervalued | O31: =IF($C$8>O29,"Overvalued","Undervalued") -> Undervalued

Sheet Football Field Analysis 
B2: Football Field Analysis
C3: Open Low | D3: Low | E3: Open High | F3: High
B4: Comps | C4: 458.39681 | D4: ='Comparable Comps '!M29 -> 458.39681 | E4: ='Comparable Comps '!N29 -> 797.35713 | F4: ='Comparable Comps '!O29 -> 899.63876
B5: DCF Bear | C5: 361.43135 | D5: 361.43135 | E5: 649.66602 | F5: 649.66602
B6: DCF Base | C6: 291.00626 | D6: 291.00626 | E6: 423.27928 | F6: 423.27928
B7: DCF Bull | C7: 246.13749 | D7: 246.13749 | E7: 320.25497 | F7: 320.25497
B8: 52W H/L | C8: 280 | D8: 280 | E8: 424 | F8: 424

Sheet Value at Risk 
B2: Date | C2: Price | D2: Returns | E2: Sorted Returns | G2: Replication | H2: Simulated Returns | J2: Calculation of Value at Risk - (Historical Method)
B3: 38372 | C3: 30.47 | D3: =(C3-C4)/C4 -> -0.55537721 | E3: 0.11163809 | G3: 1 | H3: =_xlfn.NORM.INV(RAND(),$L$4,$L$6) -> 0.052573061
B4: 39951 | C4: 68.53 | D4: =(C4-C5)/C5 -> -0.68227549 | E4: 0.11123723 | G4: 2 | H4: =_xlfn.NORM.INV(RAND(),$L$4,$L$6) -> -0.0069530143 | J4: Mean | L4: =AVERAGE(E3:E5001) -> 0.00078190574
B5: 42430 | C5: 215.69 | D5: =(C5-C6)/C6 -> 9.7737263 | E5: 0.10045918 | G5: 3 | H5: =_xlfn.NORM.INV(RAND(),$L$4,$L$6) -> -0.026635765 | J5: Median | L5: =MEDIAN(E3:E5001) -> 0.00031062332
B6: 38125 | C6: 20.02 | D6: =(C6-C7)/C7 -> -0.63593381 | E6: 0.095185996 | G6: 4 | H6: =_xlfn.NORM.INV(RAND(),$L$4,$L$6) -> 0.0008806041 | J6: Std Deviation | L6: =_xlfn.STDEV.S(E3:E5001) -> 0.017859859
B7: 39288 | C7: 54.99 | D7: =(C7-C8)/C8 -> 0.18334409 | E7: 0.089990089 | G7: 5 | H7: =_xlfn.NORM.INV(RAND(),$L$4,$L$6) -> 0.003571326 | J7: Min | L7: =MIN(E3:E5001) -> -0.12486545
B8: 38616 | C8: 46.47 | D8: =(C8-C9)/C9 -> -0.31832184 | E8: 0.089821764 | G8: 6 | H8: =_xlfn.NORM.INV(RAND(),$L$4,$L$6) -> -0.0010638101 | J8: Max | L8: =MAX(E3:E5001) -> 0.11163809
B9: 39937 | C9: 68.17 | D9: =(C9-C10)/C10 -> 0.28139098 | E9: 0.088629831 | G9: 7 | H9: =_xlfn.NORM.INV(RAND(),$L$4,$L$6) -> 0.036985053 | J9: CMP | L9: 292.3
B10: 38877 | C10: 53.2 | D10: =(C10-C11)/C11 -> -0.6968661 | E10: 0.087045362 | G10: 8 | H10: =_xlfn.NORM.INV(RAND(),$L$4,$L$6) -> 0.0072576649
B11: 43910 | C11: 175.5 | D11: =(C11-C12)/C12 -> 1.581262 | E11: 0.084337349 | G11: 9 | H11: =_xlfn.NORM.INV(RAND(),$L$4,$L$6) -> 0.00076550726 | J11: Percentile | K11: Confidence | L11: VAR % | M11: Stock Price | N11: VAR (Stock Price)
B12: 39402 | C12: 67.99 | D12: =(C12-C13)/C13 -> -0.39316316 | E12: 0.082643312 | G12: 10 | H12: =_xlfn.NORM.INV(RAND(),$L$4,$L$6) -> 0.012849571 | J12: 0.1 | K12: =1-J12 -> 0.9 | L12: =_xlfn.PERCENTILE.INC($E$3:$E$5001,J12) -> -0.018716467 | M12: =$L$9*(1-L12) -> 297.77082 | N12: =$L$9-M12 -> -5.4708232
B13: 40602 | C13: 112.04 | D13: =(C13-C14)/C14 -> -0.34746651 | E13: 0.081258444 | G13: 11 | H13: =_xlfn.NORM.INV(RAND(),$L$4,$L$6) -> -0.017057711 | J13: 0.05 | K13: =1-J13 -> 0.95 | L13: =_xlfn.PERCENTILE.INC($E$3:$E$5001,J13) -> -0.026746235 | M13: =$L$9*(1-L13) -> 300.11792 | N13: =$L$9-M13 -> -7.8179244
B14: 43921 | C14: 171.7 | D14: =(C14-C15)/C15 -> -0.091293993 | E14: 0.078517588 | G14: 12 | H14: =_xlfn.NORM.INV(RAND(),$L$4,$L$6) -> -0.021066664 | J14: 0.01 | K14: =1-J14 -> 0.99 | L14: =_xlfn.PERCENTILE.INC($E$3:$E$5001,J14) -> -0.045839836 | M14: =$L$9*(1-L14) -> 305.69898 | N14: =$L$9-M14 -> -13.398984
B15: 43972 | C15: 188.95 | D15: =(C15-C16)/C16 -> 7.1303787 | E15: 0.075106686 | G15: 13 | H15: =_xlfn.NORM.INV(RAND(),$L$4,$L$6) -> -0.017489556 | J15: 0.005 | K15: =1-J15 -> 0.995 | L15: =_xlfn.PERCENTILE.INC($E$3:$E$5001,J15) -> -0.055926611 | M15: =$L$9*(1-L15) -> 308.64735 | N15: =$L$9-M15 -> -16.347348
B16: 38177 | C16: 23.24 | D16: =(C16-C17)/C17 -> -0.85641026 | E16: 0.074433657 | G16: 14 | H16: =_xlfn.NORM.INV(RAND(),$L$4,$L$6) -> 0.0076110079
B17: 43909 | C17: 161.85 | D17: =(C17-C18)/C18 -> -0.36492054 | E17: 0.073988056 | G17: 15 | H17: =_xlfn.NORM.INV(RAND(),$L$4,$L$6) -> -0.011448206
B18: 43731 | C18: 254.85 | D18: =(C18-C19)/C19 -> 3.1819823 | E18: 0.070573409 | G18: 16 | H18: =_xlfn.NORM.INV(RAND(),$L$4,$L$6) -> 0.020478469 | J18: Calculation of Value at Risk - (Monte Carlo Simulation)
B19: 39638 | C19: 60.94 | D19: =(C19-C20)/C20 -> -0.657448 | E19: 0.070061457 | G19: 17 | H19: =_xlfn.NORM.INV(RAND(),$L$4,$L$6) -> -0.018309499
B20: 43924 | C20: 177.9 | D20: =(C20-C21)/C21 -> 2.1431095 | E20: 0.069110577 | G20: 18 | H20: =_xlfn.NORM.INV(RAND(),$L$4,$L$6) -> 0.0017979052 | J20: Mean | L20: =AVERAGE(H3:H5002) -> 0.0009760688
B21: 39756 | C21: 56.6 | D21: =(C21-C22)/C22 -> -0.19154407 | E21: 0.068529356 | G21: 19 | H21: =_xlfn.NORM.INV(RAND(),$L$4,$L$6) -> -0.016631173 | J21: Median | L21: =MEDIAN(H3:H5002) -> 0.0011815056
B22: 40001 | C22: 70.01 | D22: =(C22-C23)/C23 -> -0.69659805 | E22: 0.068365634 | G22: 20 | H22: =_xlfn.NORM.INV(RAND(),$L$4,$L$6) -> 0.0014106534 | J22: Std Deviation | L22: =_xlfn.STDEV.S(H3:H5002) -> 0.01801066
B23: 44455 | C23: 230.75 | D23: =(C23-C24)/C24 -> 2.5725344 | E23: 0.068287037 | G23: 21 | H23: =_xlfn.NORM.INV(RAND(),$L$4,$L$6) -> 0.0027101158 | J23: Min | L23: =MIN(H3:H5002) -> -0.065755786
B24: 39470 | C24: 64.59 | D24: =(C24-C25)/C25 -> -0.70090299 | E24: 0.065314201 | G24: 22 | H24: =_xlfn.NORM.INV(RAND(),$L$4,$L$6) -> 0.029750577 | J24: Max | L24: =MAX(H3:H5002) -> 0.065275837
B25: 44228 | C25: 215.95 | D25: =(C25-C26)/C26 -> -0.030266289 | E25: 0.062484625 | G25: 23 | H25: =_xlfn.NORM.INV(RAND(),$L$4,$L$6) -> -0.016472328 | J25: CMP | L25: =L9 -> 292.3
B26: 41527 | C26: 222.69 | D26: =(C26-C27)/C27 -> 2.0269131 | E26: 0.061641876 | G26: 24 | H26: =_xlfn.NORM.INV(RAND(),$L$4,$L$6) -> 0.0018995421
B27: 39596 | C27: 73.57 | D27: =(C27-C28)/C28 -> -0.52960358 | E27: 0.061462992 | G27: 25 | H27: =_xlfn.NORM.INV(RAND(),$L$4,$L$6) -> 0.0094054858 | J27: Percentile | K27: Confidence | L27: VAR % | M27: Stock Price | N27: VAR (Stock Price)
